Workbook

Sheet Breakfast
B2: Food: | E2: Insulin to Carb Ratio (ICR) | F2: 8.4 | I2: Post Meal BG Tracking | P2: Meal Builder
B3: Carb factor: | C3: =IF(C2="", "", IFERROR(VLOOKUP(C2, 'Food Chart'!A:B, 2, FALSE), "")) | E3: Target BG (mmol/L) | F3: 6.2
B4: Absorption rate: | C4: =IF(C2="", "", IFERROR(VLOOKUP(C2, 'Food Chart'!A:C, 3, FALSE), "")) | D4: =IF(C2="", "", IFERROR(VLOOKUP(C2, 'Food Chart'!A:D, 4, FALSE), "")) | E4: Correction Factor (ISF) | F4: 8.5 | I4: Time | J4: Minutes Since Bolus | K4: BG | L4: Trend | M4: Delta | P4: Food | Q4: Carb Factor | R4: Absorption Rate | S4: Weight Given | T4: Net Carbs | V4: Totle Net Carbs
B5: Weight given: | V5: Total Weight
B6: Total net carbs: | E6: Current BG (mmol/L) | F6: 6.8 | V6: Total Carb Factor
E7: Total Net Carbs (g) | V7: Calc. Absorption
B8: Food: | E8: Calculated Absorption Rate (hours)
B9: Carb factor: | C9: =IF(C8="", "", IFERROR(VLOOKUP(C8, 'Food Chart'!A:B, 2, FALSE), "")) | V9: Weight Given
B10: Absorption rate: | C10: =IF(C8="", "", IFERROR(VLOOKUP(C8, 'Food Chart'!A:C, 3, FALSE), "")) | D10: =IF(C8="", "", IFERROR(VLOOKUP(C8, 'Food Chart'!A:D, 4, FALSE), "")) | E10: Insulin On Board (IOB) | F10: 0 | V10: Total Carbs
B11: Weight given: | E11: Carbs On Board (COB) | F11: 0
B12: Total net carbs:
E13: Total Bolus | F13: =IF(OR(F2<=0,F4<=0),"",IF(AND(F6=0,F7=0),"",FLOOR(MAX(0,IF(F2>0,F7/F2,0)+IF(AND(F4>0,F3>0,F6>0),(F6-F3)/F4,0)-IF(F10>0,F10,0)-IF(F11>0,F11/F2,0)),0.05))) -> 0.05
B14: Food:
B15: Carb factor: | C15: =IF(C14="", "", IFERROR(VLOOKUP(C14, 'Food Chart'!A:B, 2, FALSE), ""))
B16: Absorption rate: | C16: =IF(C14="", "", IFERROR(VLOOKUP(C14, 'Food Chart'!A:C, 3, FALSE), "")) | D16: =IF(C14="", "", IFERROR(VLOOKUP(C14, 'Food Chart'!A:D, 4, FALSE), "")) | E16: =IFERROR(__xludf.DUMMYFUNCTION("IF(F14="""", ""Bolus time"", IF(ISTEXT(F14), F14, REGEXREPLACE(REGEXREPLACE(TEXT(FLOOR(F14, 0.05), ""0.00""), ""([.,]\d)0$"", ""$1""), ""[.,]0$"", """") ) & "" U bolus at"" )"),"Bolus time") -> Bolus time | J16: .
B17: Weight given: | E17: Desired start time
B18: Total net carbs: | E18: Breakfast start
E19: Time between | F19: =IF(OR(F18="",F16=""),"",ROUND((F18-F16)*24*60,0)&" minutes")
B20: Food: | I20: .
B21: Carb factor: | C21: =IF(C20="", "", IFERROR(VLOOKUP(C20, 'Food Chart'!A:B, 2, FALSE), ""))
B22: Absorption rate: | C22: =IF(C20="", "", IFERROR(VLOOKUP(C20, 'Food Chart'!A:C, 3, FALSE), "")) | D22: =IF(C20="", "", IFERROR(VLOOKUP(C20, 'Food Chart'!A:D, 4, FALSE), "")) | E22: - Notes -
B23: Weight given:
B24: Total net carbs:
B26: Food:
B27: Carb factor: | C27: =IF(C26="", "", IFERROR(VLOOKUP(C26, 'Food Chart'!A:B, 2, FALSE), ""))
B28: Absorption rate: | C28: =IF(C26="", "", IFERROR(VLOOKUP(C26, 'Food Chart'!A:C, 3, FALSE), "")) | D28: =IF(C26="", "", IFERROR(VLOOKUP(C26, 'Food Chart'!A:D, 4, FALSE), ""))
B29: Weight given:
B30: Total net carbs:
B32: Food:
B33: Carb factor: | C33: =IF(C32="", "", IFERROR(VLOOKUP(C32, 'Food Chart'!A:B, 2, FALSE), ""))
B34: Absorption rate: | C34: =IF(C32="", "", IFERROR(VLOOKUP(C32, 'Food Chart'!A:C, 3, FALSE), "")) | D34: =IF(C32="", "", IFERROR(VLOOKUP(C32, 'Food Chart'!A:D, 4, FALSE), ""))
B35: Weight given:
B36: Total net carbs:
B38: Food:
B39: Carb factor: | C39: =IF(C38="", "", IFERROR(VLOOKUP(C38, 'Food Chart'!A:B, 2, FALSE), ""))
B40: Absorption rate: | C40: =IF(C38="", "", IFERROR(VLOOKUP(C38, 'Food Chart'!A:C, 3, FALSE), "")) | D40: =IF(C38="", "", IFERROR(VLOOKUP(C38, 'Food Chart'!A:D, 4, FALSE), ""))
B41: Weight given:
B42: Total net carbs:
B44: Food:
B45: Carb factor: | C45: =IF(C44="", "", IFERROR(VLOOKUP(C44, 'Food Chart'!A:B, 2, FALSE), ""))
...

Sheet Morning Snack
B2: Food: | E2: Insulin to Carb Ratio (ICR) | F2: 20.8 | I2: Post Meal BG Tracking | P2: Meal Builder
B3: Carb factor: | C3: =IF(C2="", "", IFERROR(VLOOKUP(C2, 'Food Chart'!A:B, 2, FALSE), "")) | E3: Target BG (mmol/L) | F3: 6.2
B4: Absorption rate: | C4: =IF(C2="", "", IFERROR(VLOOKUP(C2, 'Food Chart'!A:C, 3, FALSE), "")) | D4: =IF(C2="", "", IFERROR(VLOOKUP(C2, 'Food Chart'!A:D, 4, FALSE), "")) | E4: Correction Factor (ISF) | F4: 8.5 | I4: Time | J4: Minutes Since Bolus | K4: BG | L4: Trend | M4: Delta | P4: Food | Q4: Carb Factor | R4: Absorption Rate | S4: Weight Given | T4: Net Carbs | V4: Totle Net Carbs
B5: Weight given: | V5: Total Weight
B6: Total net carbs: | E6: Current BG (mmol/L) | F6: 10.4 | G6: now | V6: Total Carb Factor
E7: Total Net Carbs (g) | V7: Calc. Absorption
B8: Food: | E8: Calculated Absorption Rate (hours)
B9: Carb factor: | C9: =IF(C8="", "", IFERROR(VLOOKUP(C8, 'Food Chart'!A:B, 2, FALSE), "")) | V9: Weight Given
B10: Absorption rate: | C10: =IF(C8="", "", IFERROR(VLOOKUP(C8, 'Food Chart'!A:C, 3, FALSE), "")) | D10: =IF(C8="", "", IFERROR(VLOOKUP(C8, 'Food Chart'!A:D, 4, FALSE), "")) | E10: Insulin On Board (IOB) | F10: 1.22 | V10: Total Carbs
B11: Weight given: | E11: Carbs On Board (COB) | F11: 15.2
B12: Total net carbs:
E13: Total Bolus | F13: =IF(OR(F2<=0,F4<=0),"",IF(AND(F6=0,F7=0),"",FLOOR(MAX(0,IF(F2>0,F7/F2,0)+IF(AND(F4>0,F3>0,F6>0),(F6-F3)/F4,0)-IF(F10>0,F10,0)-IF(F11>0,F11/F2,0)),0.05))) -> 0
B14: Food:
B15: Carb factor: | C15: =IF(C14="", "", IFERROR(VLOOKUP(C14, 'Food Chart'!A:B, 2, FALSE), ""))
B16: Absorption rate: | C16: =IF(C14="", "", IFERROR(VLOOKUP(C14, 'Food Chart'!A:C, 3, FALSE), "")) | D16: =IF(C14="", "", IFERROR(VLOOKUP(C14, 'Food Chart'!A:D, 4, FALSE), "")) | E16: =IFERROR(__xludf.DUMMYFUNCTION("IF(F14="""", ""Bolus time"", IF(ISTEXT(F14), F14, REGEXREPLACE(REGEXREPLACE(TEXT(FLOOR(F14, 0.05), ""0.00""), ""([.,]\d)0$"", ""$1""), ""[.,]0$"", """") ) & "" U bolus at"" )"),"Bolus time") -> Bolus time
B17: Weight given: | E17: Desired start time
B18: Total net carbs: | E18: Morning snack start
E19: Time between | F19: =IF(OR(F18="",F16=""),"",ROUND((F18-F16)*24*60,0)&" minutes")
B20: Food:
B21: Carb factor: | C21: =IF(C20="", "", IFERROR(VLOOKUP(C20, 'Food Chart'!A:B, 2, FALSE), ""))
B22: Absorption rate: | C22: =IF(C20="", "", IFERROR(VLOOKUP(C20, 'Food Chart'!A:C, 3, FALSE), "")) | D22: =IF(C20="", "", IFERROR(VLOOKUP(C20, 'Food Chart'!A:D, 4, FALSE), "")) | E22: - Notes -
B23: Weight given:
B24: Total net carbs:
B26: Food:
B27: Carb factor: | C27: =IF(C26="", "", IFERROR(VLOOKUP(C26, 'Food Chart'!A:B, 2, FALSE), ""))
B28: Absorption rate: | C28: =IF(C26="", "", IFERROR(VLOOKUP(C26, 'Food Chart'!A:C, 3, FALSE), "")) | D28: =IF(C26="", "", IFERROR(VLOOKUP(C26, 'Food Chart'!A:D, 4, FALSE), ""))
B29: Weight given:
B30: Total net carbs:
B32: Food:
B33: Carb factor: | C33: =IF(C32="", "", IFERROR(VLOOKUP(C32, 'Food Chart'!A:B, 2, FALSE), ""))
B34: Absorption rate: | C34: =IF(C32="", "", IFERROR(VLOOKUP(C32, 'Food Chart'!A:C, 3, FALSE), "")) | D34: =IF(C32="", "", IFERROR(VLOOKUP(C32, 'Food Chart'!A:D, 4, FALSE), ""))
B35: Weight given:
B36: Total net carbs:
B38: Food:
B39: Carb factor: | C39: =IF(C38="", "", IFERROR(VLOOKUP(C38, 'Food Chart'!A:B, 2, FALSE), ""))
B40: Absorption rate: | C40: =IF(C38="", "", IFERROR(VLOOKUP(C38, 'Food Chart'!A:C, 3, FALSE), "")) | D40: =IF(C38="", "", IFERROR(VLOOKUP(C38, 'Food Chart'!A:D, 4, FALSE), ""))
B41: Weight given:
B42: Total net carbs:
B44: Food:
B45: Carb factor: | C45: =IF(C44="", "", IFERROR(VLOOKUP(C44, 'Food Chart'!A:B, 2, FALSE), ""))
...

Sheet Lunch
B2: Food: | E2: Insulin to Carb Ratio (ICR) | F2: 20.8 | I2: Post Meal BG Tracking | P2: Meal Builder
B3: Carb factor: | C3: =IF(C2="", "", IFERROR(VLOOKUP(C2, 'Food Chart'!A:B, 2, FALSE), "")) | E3: Target BG (mmol/L) | F3: 6.2
B4: Absorption rate: | C4: =IF(C2="", "", IFERROR(VLOOKUP(C2, 'Food Chart'!A:C, 3, FALSE), "")) | D4: =IF(C2="", "", IFERROR(VLOOKUP(C2, 'Food Chart'!A:D, 4, FALSE), "")) | E4: Correction Factor (ISF) | F4: 8.5 | I4: Time | J4: Minutes Since Bolus | K4: BG | L4: Trend | M4: Delta | P4: Food | Q4: Carb Factor | R4: Absorption Rate | S4: Weight Given | T4: Net Carbs | V4: Totle Net Carbs
B5: Weight given: | V5: Total Weight
B6: Total net carbs: | E6: Current BG (mmol/L) | F6: 10.4 | G6: now | V6: Total Carb Factor
E7: Total Net Carbs (g) | V7: Calc. Absorption
B8: Food: | E8: Calculated Absorption Rate (hours)
B9: Carb factor: | C9: =IF(C8="", "", IFERROR(VLOOKUP(C8, 'Food Chart'!A:B, 2, FALSE), "")) | V9: Weight Given
B10: Absorption rate: | C10: =IF(C8="", "", IFERROR(VLOOKUP(C8, 'Food Chart'!A:C, 3, FALSE), "")) | D10: =IF(C8="", "", IFERROR(VLOOKUP(C8, 'Food Chart'!A:D, 4, FALSE), "")) | E10: Insulin On Board (IOB) | F10: 1.22 | V10: Total Carbs
B11: Weight given: | E11: Carbs On Board (COB) | F11: 15.2
B12: Total net carbs:
E13: Total Bolus | F13: =IF(OR(F2<=0,F4<=0),"",IF(AND(F6=0,F7=0),"",FLOOR(MAX(0,IF(F2>0,F7/F2,0)+IF(AND(F4>0,F3>0,F6>0),(F6-F3)/F4,0)-IF(F10>0,F10,0)-IF(F11>0,F11/F2,0)),0.05))) -> 0
B14: Food:
B15: Carb factor: | C15: =IF(C14="", "", IFERROR(VLOOKUP(C14, 'Food Chart'!A:B, 2, FALSE), ""))
B16: Absorption rate: | C16: =IF(C14="", "", IFERROR(VLOOKUP(C14, 'Food Chart'!A:C, 3, FALSE), "")) | D16: =IF(C14="", "", IFERROR(VLOOKUP(C14, 'Food Chart'!A:D, 4, FALSE), "")) | E16: =IFERROR(__xludf.DUMMYFUNCTION("IF(F14="""", ""Bolus time"", IF(ISTEXT(F14), F14, REGEXREPLACE(REGEXREPLACE(TEXT(FLOOR(F14, 0.05), ""0.00""), ""([.,]\d)0$"", ""$1""), ""[.,]0$"", """") ) & "" U bolus at"" )"),"Bolus time") -> Bolus time
B17: Weight given: | E17: Desired start time
B18: Total net carbs: | E18: Lunch start
E19: Time between | F19: =IF(OR(F18="",F16=""),"",ROUND((F18-F16)*24*60,0)&" minutes")
B20: Food:
B21: Carb factor: | C21: =IF(C20="", "", IFERROR(VLOOKUP(C20, 'Food Chart'!A:B, 2, FALSE), ""))
B22: Absorption rate: | C22: =IF(C20="", "", IFERROR(VLOOKUP(C20, 'Food Chart'!A:C, 3, FALSE), "")) | D22: =IF(C20="", "", IFERROR(VLOOKUP(C20, 'Food Chart'!A:D, 4, FALSE), "")) | E22: - Notes -
B23: Weight given:
B24: Total net carbs:
B26: Food:
B27: Carb factor: | C27: =IF(C26="", "", IFERROR(VLOOKUP(C26, 'Food Chart'!A:B, 2, FALSE), ""))
B28: Absorption rate: | C28: =IF(C26="", "", IFERROR(VLOOKUP(C26, 'Food Chart'!A:C, 3, FALSE), "")) | D28: =IF(C26="", "", IFERROR(VLOOKUP(C26, 'Food Chart'!A:D, 4, FALSE), ""))
B29: Weight given:
B30: Total net carbs:
B32: Food:
B33: Carb factor: | C33: =IF(C32="", "", IFERROR(VLOOKUP(C32, 'Food Chart'!A:B, 2, FALSE), ""))
B34: Absorption rate: | C34: =IF(C32="", "", IFERROR(VLOOKUP(C32, 'Food Chart'!A:C, 3, FALSE), "")) | D34: =IF(C32="", "", IFERROR(VLOOKUP(C32, 'Food Chart'!A:D, 4, FALSE), ""))
B35: Weight given:
B36: Total net carbs:
B38: Food:
B39: Carb factor: | C39: =IF(C38="", "", IFERROR(VLOOKUP(C38, 'Food Chart'!A:B, 2, FALSE), ""))
B40: Absorption rate: | C40: =IF(C38="", "", IFERROR(VLOOKUP(C38, 'Food Chart'!A:C, 3, FALSE), "")) | D40: =IF(C38="", "", IFERROR(VLOOKUP(C38, 'Food Chart'!A:D, 4, FALSE), ""))
B41: Weight given:
B42: Total net carbs:
B44: Food:
B45: Carb factor: | C45: =IF(C44="", "", IFERROR(VLOOKUP(C44, 'Food Chart'!A:B, 2, FALSE), ""))
...

Sheet Afternoon Snack
B2: Food: | E2: Insulin to Carb Ratio (ICR) | F2: 20.8 | I2: Post Meal BG Tracking | P2: Meal Builder
B3: Carb factor: | C3: =IF(C2="", "", IFERROR(VLOOKUP(C2, 'Food Chart'!A:B, 2, FALSE), "")) | E3: Target BG (mmol/L) | F3: 6.2
B4: Absorption rate: | C4: =IF(C2="", "", IFERROR(VLOOKUP(C2, 'Food Chart'!A:C, 3, FALSE), "")) | D4: =IF(C2="", "", IFERROR(VLOOKUP(C2, 'Food Chart'!A:D, 4, FALSE), "")) | E4: Correction Factor (ISF) | F4: 8.5 | I4: Time | J4: Minutes Since Bolus | K4: BG | L4: Trend | M4: Delta | P4: Food | Q4: Carb Factor | R4: Absorption Rate | S4: Weight Given | T4: Net Carbs | V4: Totle Net Carbs
B5: Weight given: | V5: Total Weight
B6: Total net carbs: | E6: Current BG (mmol/L) | F6: 10.4 | G6: now | V6: Total Carb Factor
E7: Total Net Carbs (g) | V7: Calc. Absorption
B8: Food: | E8: Calculated Absorption Rate (hours)
B9: Carb factor: | C9: =IF(C8="", "", IFERROR(VLOOKUP(C8, 'Food Chart'!A:B, 2, FALSE), "")) | V9: Weight Given
B10: Absorption rate: | C10: =IF(C8="", "", IFERROR(VLOOKUP(C8, 'Food Chart'!A:C, 3, FALSE), "")) | D10: =IF(C8="", "", IFERROR(VLOOKUP(C8, 'Food Chart'!A:D, 4, FALSE), "")) | E10: Insulin On Board (IOB) | F10: 1.22 | V10: Total Carbs
B11: Weight given: | E11: Carbs On Board (COB) | F11: 15.2
B12: Total net carbs:
E13: Total Bolus | F13: =IF(OR(F2<=0,F4<=0),"",IF(AND(F6=0,F7=0),"",FLOOR(MAX(0,IF(F2>0,F7/F2,0)+IF(AND(F4>0,F3>0,F6>0),(F6-F3)/F4,0)-IF(F10>0,F10,0)-IF(F11>0,F11/F2,0)),0.05))) -> 0
B14: Food:
B15: Carb factor: | C15: =IF(C14="", "", IFERROR(VLOOKUP(C14, 'Food Chart'!A:B, 2, FALSE), ""))
B16: Absorption rate: | C16: =IF(C14="", "", IFERROR(VLOOKUP(C14, 'Food Chart'!A:C, 3, FALSE), "")) | D16: =IF(C14="", "", IFERROR(VLOOKUP(C14, 'Food Chart'!A:D, 4, FALSE), "")) | E16: =IFERROR(__xludf.DUMMYFUNCTION("IF(F14="""", ""Bolus time"", IF(ISTEXT(F14), F14, REGEXREPLACE(REGEXREPLACE(TEXT(FLOOR(F14, 0.05), ""0.00""), ""([.,]\d)0$"", ""$1""), ""[.,]0$"", """") ) & "" U bolus at"" )"),"Bolus time") -> Bolus time
B17: Weight given: | E17: Desired start time
B18: Total net carbs: | E18: Afternoon snack start
E19: Time between | F19: =IF(OR(F18="",F16=""),"",ROUND((F18-F16)*24*60,0)&" minutes")
B20: Food:
B21: Carb factor: | C21: =IF(C20="", "", IFERROR(VLOOKUP(C20, 'Food Chart'!A:B, 2, FALSE), ""))
B22: Absorption rate: | C22: =IF(C20="", "", IFERROR(VLOOKUP(C20, 'Food Chart'!A:C, 3, FALSE), "")) | D22: =IF(C20="", "", IFERROR(VLOOKUP(C20, 'Food Chart'!A:D, 4, FALSE), "")) | E22: - Notes -
B23: Weight given:
B24: Total net carbs:
B26: Food:
B27: Carb factor: | C27: =IF(C26="", "", IFERROR(VLOOKUP(C26, 'Food Chart'!A:B, 2, FALSE), ""))
B28: Absorption rate: | C28: =IF(C26="", "", IFERROR(VLOOKUP(C26, 'Food Chart'!A:C, 3, FALSE), "")) | D28: =IF(C26="", "", IFERROR(VLOOKUP(C26, 'Food Chart'!A:D, 4, FALSE), ""))
B29: Weight given:
B30: Total net carbs:
B32: Food:
B33: Carb factor: | C33: =IF(C32="", "", IFERROR(VLOOKUP(C32, 'Food Chart'!A:B, 2, FALSE), ""))
B34: Absorption rate: | C34: =IF(C32="", "", IFERROR(VLOOKUP(C32, 'Food Chart'!A:C, 3, FALSE), "")) | D34: =IF(C32="", "", IFERROR(VLOOKUP(C32, 'Food Chart'!A:D, 4, FALSE), ""))
B35: Weight given:
B36: Total net carbs:
B38: Food:
B39: Carb factor: | C39: =IF(C38="", "", IFERROR(VLOOKUP(C38, 'Food Chart'!A:B, 2, FALSE), ""))
B40: Absorption rate: | C40: =IF(C38="", "", IFERROR(VLOOKUP(C38, 'Food Chart'!A:C, 3, FALSE), "")) | D40: =IF(C38="", "", IFERROR(VLOOKUP(C38, 'Food Chart'!A:D, 4, FALSE), ""))
B41: Weight given:
B42: Total net carbs:
B44: Food:
B45: Carb factor: | C45: =IF(C44="", "", IFERROR(VLOOKUP(C44, 'Food Chart'!A:B, 2, FALSE), ""))
...

Sheet Dinner
B2: Food: | E2: Insulin to Carb Ratio (ICR) | F2: 20.8 | I2: Post Meal BG Tracking | P2: Meal Builder
B3: Carb factor: | C3: =IF(C2="", "", IFERROR(VLOOKUP(C2, 'Food Chart'!A:B, 2, FALSE), "")) | E3: Target BG (mmol/L) | F3: 6.2
B4: Absorption rate: | C4: =IF(C2="", "", IFERROR(VLOOKUP(C2, 'Food Chart'!A:C, 3, FALSE), "")) | D4: =IF(C2="", "", IFERROR(VLOOKUP(C2, 'Food Chart'!A:D, 4, FALSE), "")) | E4: Correction Factor (ISF) | F4: 8.5 | I4: Time | J4: Minutes Since Bolus | K4: BG | L4: Trend | M4: Delta | P4: Food | Q4: Carb Factor | R4: Absorption Rate | S4: Weight Given | T4: Net Carbs | V4: Totle Net Carbs
B5: Weight given: | V5: Total Weight
B6: Total net carbs: | E6: Current BG (mmol/L) | F6: 10.6 | V6: Total Carb Factor
E7: Total Net Carbs (g) | V7: Calc. Absorption
B8: Food: | E8: Calculated Absorption Rate (hours)
B9: Carb factor: | C9: =IF(C8="", "", IFERROR(VLOOKUP(C8, 'Food Chart'!A:B, 2, FALSE), "")) | V9: Weight Given
B10: Absorption rate: | C10: =IF(C8="", "", IFERROR(VLOOKUP(C8, 'Food Chart'!A:C, 3, FALSE), "")) | D10: =IF(C8="", "", IFERROR(VLOOKUP(C8, 'Food Chart'!A:D, 4, FALSE), "")) | E10: Insulin On Board (IOB) | F10: 0.5 | V10: Total Carbs
B11: Weight given: | E11: Carbs On Board (COB) | F11: 0
B12: Total net carbs:
E13: Total Bolus | F13: =IF(OR(F2<=0,F4<=0),"",IF(AND(F6=0,F7=0),"",FLOOR(MAX(0,IF(F2>0,F7/F2,0)+IF(AND(F4>0,F3>0,F6>0),(F6-F3)/F4,0)-IF(F10>0,F10,0)-IF(F11>0,F11/F2,0)),0.05))) -> 0
B14: Food:
B15: Carb factor: | C15: =IF(C14="", "", IFERROR(VLOOKUP(C14, 'Food Chart'!A:B, 2, FALSE), ""))
B16: Absorption rate: | C16: =IF(C14="", "", IFERROR(VLOOKUP(C14, 'Food Chart'!A:C, 3, FALSE), "")) | D16: =IF(C14="", "", IFERROR(VLOOKUP(C14, 'Food Chart'!A:D, 4, FALSE), "")) | E16: =IFERROR(__xludf.DUMMYFUNCTION("IF(F14="""", ""Bolus time"", IF(ISTEXT(F14), F14, REGEXREPLACE(REGEXREPLACE(TEXT(FLOOR(F14, 0.05), ""0.00""), ""([.,]\d)0$"", ""$1""), ""[.,]0$"", """") ) & "" U bolus at"" )"),"Bolus time") -> Bolus time
B17: Weight given: | E17: Desired start time
B18: Total net carbs: | E18: Dinner start
E19: Time between | F19: =IF(OR(F18="",F16=""),"",ROUND((F18-F16)*24*60,0)&" minutes")
B20: Food:
B21: Carb factor: | C21: =IF(C20="", "", IFERROR(VLOOKUP(C20, 'Food Chart'!A:B, 2, FALSE), ""))
B22: Absorption rate: | C22: =IF(C20="", "", IFERROR(VLOOKUP(C20, 'Food Chart'!A:C, 3, FALSE), "")) | D22: =IF(C20="", "", IFERROR(VLOOKUP(C20, 'Food Chart'!A:D, 4, FALSE), "")) | E22: - Notes -
B23: Weight given:
B24: Total net carbs:
B26: Food:
B27: Carb factor: | C27: =IF(C26="", "", IFERROR(VLOOKUP(C26, 'Food Chart'!A:B, 2, FALSE), ""))
B28: Absorption rate: | C28: =IF(C26="", "", IFERROR(VLOOKUP(C26, 'Food Chart'!A:C, 3, FALSE), "")) | D28: =IF(C26="", "", IFERROR(VLOOKUP(C26, 'Food Chart'!A:D, 4, FALSE), ""))
B29: Weight given:
B30: Total net carbs:
B32: Food:
B33: Carb factor: | C33: =IF(C32="", "", IFERROR(VLOOKUP(C32, 'Food Chart'!A:B, 2, FALSE), ""))
B34: Absorption rate: | C34: =IF(C32="", "", IFERROR(VLOOKUP(C32, 'Food Chart'!A:C, 3, FALSE), "")) | D34: =IF(C32="", "", IFERROR(VLOOKUP(C32, 'Food Chart'!A:D, 4, FALSE), ""))
B35: Weight given:
B36: Total net carbs:
B38: Food:
B39: Carb factor: | C39: =IF(C38="", "", IFERROR(VLOOKUP(C38, 'Food Chart'!A:B, 2, FALSE), ""))
B40: Absorption rate: | C40: =IF(C38="", "", IFERROR(VLOOKUP(C38, 'Food Chart'!A:C, 3, FALSE), "")) | D40: =IF(C38="", "", IFERROR(VLOOKUP(C38, 'Food Chart'!A:D, 4, FALSE), ""))
B41: Weight given:
B42: Total net carbs:
B44: Food:
B45: Carb factor: | C45: =IF(C44="", "", IFERROR(VLOOKUP(C44, 'Food Chart'!A:B, 2, FALSE), ""))
...

Sheet Evening Snack
B2: Food: | E2: Insulin to Carb Ratio (ICR) | F2: 20.8 | I2: Post Meal BG Tracking | P2: Meal Builder
B3: Carb factor: | C3: =IF(C2="", "", IFERROR(VLOOKUP(C2, 'Food Chart'!A:B, 2, FALSE), "")) | E3: Target BG (mmol/L) | F3: 6.2
B4: Absorption rate: | C4: =IF(C2="", "", IFERROR(VLOOKUP(C2, 'Food Chart'!A:C, 3, FALSE), "")) | D4: =IF(C2="", "", IFERROR(VLOOKUP(C2, 'Food Chart'!A:D, 4, FALSE), "")) | E4: Correction Factor (ISF) | F4: 8.5 | I4: Time | J4: Minutes Since Bolus | K4: BG | L4: Trend | M4: Delta | P4: Food | Q4: Carb Factor | R4: Absorption Rate | S4: Weight Given | T4: Net Carbs | V4: Totle Net Carbs
B5: Weight given: | V5: Total Weight
B6: Total net carbs: | E6: Current BG (mmol/L) | F6: 10.4 | G6: now | V6: Total Carb Factor
E7: Total Net Carbs (g) | V7: Calc. Absorption
B8: Food: | E8: Calculated Absorption Rate (hours)
B9: Carb factor: | C9: =IF(C8="", "", IFERROR(VLOOKUP(C8, 'Food Chart'!A:B, 2, FALSE), "")) | V9: Weight Given
B10: Absorption rate: | C10: =IF(C8="", "", IFERROR(VLOOKUP(C8, 'Food Chart'!A:C, 3, FALSE), "")) | D10: =IF(C8="", "", IFERROR(VLOOKUP(C8, 'Food Chart'!A:D, 4, FALSE), "")) | E10: Insulin On Board (IOB) | F10: 1.22 | V10: Total Carbs
B11: Weight given: | E11: Carbs On Board (COB) | F11: 15.2
B12: Total net carbs:
E13: Total Bolus | F13: =IF(OR(F2<=0,F4<=0),"",IF(AND(F6=0,F7=0),"",FLOOR(MAX(0,IF(F2>0,F7/F2,0)+IF(AND(F4>0,F3>0,F6>0),(F6-F3)/F4,0)-IF(F10>0,F10,0)-IF(F11>0,F11/F2,0)),0.05))) -> 0
B14: Food:
B15: Carb factor: | C15: =IF(C14="", "", IFERROR(VLOOKUP(C14, 'Food Chart'!A:B, 2, FALSE), ""))
B16: Absorption rate: | C16: =IF(C14="", "", IFERROR(VLOOKUP(C14, 'Food Chart'!A:C, 3, FALSE), "")) | D16: =IF(C14="", "", IFERROR(VLOOKUP(C14, 'Food Chart'!A:D, 4, FALSE), "")) | E16: =IFERROR(__xludf.DUMMYFUNCTION("IF(F14="""", ""Bolus time"", IF(ISTEXT(F14), F14, REGEXREPLACE(REGEXREPLACE(TEXT(FLOOR(F14, 0.05), ""0.00""), ""([.,]\d)0$"", ""$1""), ""[.,]0$"", """") ) & "" U bolus at"" )"),"Bolus time") -> Bolus time
B17: Weight given: | E17: Desired start time
B18: Total net carbs: | E18: Evening snack start
E19: Time between | F19: =IF(OR(F18="",F16=""),"",ROUND((F18-F16)*24*60,0)&" minutes")
B20: Food:
B21: Carb factor: | C21: =IF(C20="", "", IFERROR(VLOOKUP(C20, 'Food Chart'!A:B, 2, FALSE), ""))
B22: Absorption rate: | C22: =IF(C20="", "", IFERROR(VLOOKUP(C20, 'Food Chart'!A:C, 3, FALSE), "")) | D22: =IF(C20="", "", IFERROR(VLOOKUP(C20, 'Food Chart'!A:D, 4, FALSE), "")) | E22: - Notes -
B23: Weight given:
B24: Total net carbs:
B26: Food:
B27: Carb factor: | C27: =IF(C26="", "", IFERROR(VLOOKUP(C26, 'Food Chart'!A:B, 2, FALSE), ""))
B28: Absorption rate: | C28: =IF(C26="", "", IFERROR(VLOOKUP(C26, 'Food Chart'!A:C, 3, FALSE), "")) | D28: =IF(C26="", "", IFERROR(VLOOKUP(C26, 'Food Chart'!A:D, 4, FALSE), ""))
B29: Weight given:
B30: Total net carbs:
B32: Food:
B33: Carb factor: | C33: =IF(C32="", "", IFERROR(VLOOKUP(C32, 'Food Chart'!A:B, 2, FALSE), ""))
B34: Absorption rate: | C34: =IF(C32="", "", IFERROR(VLOOKUP(C32, 'Food Chart'!A:C, 3, FALSE), "")) | D34: =IF(C32="", "", IFERROR(VLOOKUP(C32, 'Food Chart'!A:D, 4, FALSE), ""))
B35: Weight given:
B36: Total net carbs:
B38: Food:
B39: Carb factor: | C39: =IF(C38="", "", IFERROR(VLOOKUP(C38, 'Food Chart'!A:B, 2, FALSE), ""))
B40: Absorption rate: | C40: =IF(C38="", "", IFERROR(VLOOKUP(C38, 'Food Chart'!A:C, 3, FALSE), "")) | D40: =IF(C38="", "", IFERROR(VLOOKUP(C38, 'Food Chart'!A:D, 4, FALSE), ""))
B41: Weight given:
B42: Total net carbs:
B44: Food:
B45: Carb factor: | C45: =IF(C44="", "", IFERROR(VLOOKUP(C44, 'Food Chart'!A:B, 2, FALSE), ""))
...

Sheet Food Chart
A1: Food | B1: Carb Factor | C1: Absorption Rate (hours)
A2: Advent Calendar Chocolate | B2: 1 | C2: 2
A3: All Purpose Flour | B3: 0.7 | C3: 3
A4: Almond Flour | B4: 0.13 | C4: 4
A5: Annie's Mac & Cheese | B5: 0.27 | C5: 3
A6: Annie's Mac & Cheese - Shells | B6: 0.29 | C6: 3
A7: Apple | B7: 0.13 | C7: 3
A8: Avafina Plant Based Cream Cheese | B8: 0.13 | C8: 3
A9: Avocado | B9: 0.02 | C9: 3
A10: Baby Corn (per corn) | B10: 0.15 | C10: 3
A11: Baked Potato (with skin) | B11: 0.2 | C11: 3
A12: Baked Potato (without skin) | B12: 0.21 | C12: 3
A13: Baking Powder | B13: 0 | C13: 3.5
... A306: Water | B306: 0 | C306: 3

Sheet Food Search Index
A1: Date | B1: Meal | C1: Food | D1: Carb Factor | E1: Weight (g) | F1: Net Carbs | G1: Doc URL
A2: 46097 | B2: Breakfast | C2: Les Grains St-Méthode Multi-Cereal Bread (Per Slice) | D2: 10 | E2: 1.5 | F2: 15 | G2: https://docs.google.com/open?id=1o9L2lTrBDlbyB_v9oW9OkkSzVIujkvkuoJLiFUHhdZA
A3: 46097 | B3: Breakfast | C3: Kraft Smooth Peanut Butter | D3: 0.13 | E3: 15 | F3: 2 | G3: https://docs.google.com/open?id=1o9L2lTrBDlbyB_v9oW9OkkSzVIujkvkuoJLiFUHhdZA
A4: 46097 | B4: Breakfast | C4: Double Fruit 'No Sugar Added' Jam (Strawberry / Blueberry) | D4: 0.27 | E4: 8 | F4: 2.2 | G4: https://docs.google.com/open?id=1o9L2lTrBDlbyB_v9oW9OkkSzVIujkvkuoJLiFUHhdZA
A5: 46097 | B5: Breakfast | C5: Apple | D5: 0.13 | E5: 45 | F5: 5.9 | G5: https://docs.google.com/open?id=1o9L2lTrBDlbyB_v9oW9OkkSzVIujkvkuoJLiFUHhdZA
A6: 46097 | B6: Morning Snack | C6: Apple | D6: 0.13 | E6: 46 | F6: 6 | G6: https://docs.google.com/open?id=1o9L2lTrBDlbyB_v9oW9OkkSzVIujkvkuoJLiFUHhdZA
A7: 46097 | B7: Morning Snack | C7: Blueberries | D7: 0.12 | E7: 38 | F7: 4.5 | G7: https://docs.google.com/open?id=1o9L2lTrBDlbyB_v9oW9OkkSzVIujkvkuoJLiFUHhdZA
A8: 46097 | B8: Dinner | C8: Les Grains St-Méthode Multi-Cereal Bread (Per Slice) | D8: 10 | E8: 1.5 | F8: 15 | G8: https://docs.google.com/open?id=1o9L2lTrBDlbyB_v9oW9OkkSzVIujkvkuoJLiFUHhdZA
A9: 46097 | B9: Dinner | C9: Sugar-Free Ketchup | D9: 0.07 | E9: 21 | F9: 1.5 | G9: https://docs.google.com/open?id=1o9L2lTrBDlbyB_v9oW9OkkSzVIujkvkuoJLiFUHhdZA
A10: 46097 | B10: Dinner | C10: Veggies and Dip (per serving) | D10: 1 | E10: 1 | F10: 1 | G10: https://docs.google.com/open?id=1o9L2lTrBDlbyB_v9oW9OkkSzVIujkvkuoJLiFUHhdZA
A11: 46096 | B11: Breakfast | C11: Walmart Cheese Croissant (by croissant) | D11: 12 | E11: 1 | F11: 12 | G11: https://docs.google.com/open?id=1kD2eLH7Asnu83kjTVOV3tHJHaj_MBJzuGGBeFPpv8Zg
A12: 46096 | B12: Breakfast | C12: Strawberries | D12: 0.05 | E12: 50 | F12: 2.5 | G12: https://docs.google.com/open?id=1kD2eLH7Asnu83kjTVOV3tHJHaj_MBJzuGGBeFPpv8Zg
A13: 46096 | B13: Lunch | C13: Annie's Mac & Cheese | D13: 0.27 | E13: 110 | F13: 29.7 | G13: https://docs.google.com/open?id=1kD2eLH7Asnu83kjTVOV3tHJHaj_MBJzuGGBeFPpv8Zg
... A16: 46096 | B16: Afternoon Snack | C16: Vegetable Things - Original | D16: 0.6 | E16: 10 | F16: 6 | G16: https://docs.google.com/open?id=1kD2eLH7Asnu83kjTVOV3tHJHaj_MBJzuGGBeFPpv8Zg
A17: 46096 | B17: Afternoon Snack | C17: Cucumber | D17: 0 | G17: https://docs.google.com/open?id=1kD2eLH7Asnu83kjTVOV3tHJHaj_MBJzuGGBeFPpv8Zg
A18: 46096 | B18: Dinner | C18: Fontaine Sante Extra Firm Tofu (Costco) | D18: 0 | E18: 30 | F18: 0 | G18: https://docs.google.com/open?id=1kD2eLH7Asnu83kjTVOV3tHJHaj_MBJzuGGBeFPpv8Zg
A19: 46096 | B19: Dinner | C19: Quinoa (cooked) | D19: 0.19 | E19: 60 | F19: 11.4 | G19: https://docs.google.com/open?id=1kD2eLH7Asnu83kjTVOV3tHJHaj_MBJzuGGBeFPpv8Zg
A20: 46096 | B20: Dinner | C20: Kirkland Frozen Mixed Vegetables (Veggies) | D20: 0.02 | E20: 100 | F20: 2 | G20: https://docs.google.com/open?id=1kD2eLH7Asnu83kjTVOV3tHJHaj_MBJzuGGBeFPpv8Zg
A21: 46096 | B21: Dinner | C21: Peanut Sauce | D21: 0.08 | E21: 69 | F21: 5.5 | G21: https://docs.google.com/open?id=1kD2eLH7Asnu83kjTVOV3tHJHaj_MBJzuGGBeFPpv8Zg
A22: 46096 | B22: Evening Snack | C22: Bell Pepper | D22: 0.05 | E22: 27 | F22: 1.4 | G22: https://docs.google.com/open?id=1kD2eLH7Asnu83kjTVOV3tHJHaj_MBJzuGGBeFPpv8Zg
A23: 46095 | B23: Breakfast | C23: Cinnamon Toast Crunch (cereal) | D23: 0.76 | E23: 45 | F23: 34.2 | G23: https://docs.google.com/open?id=1h9CmVCxFuDLMFbGBaBznFKnrVbxtmirpfh28FMmvHFA
A24: 46095 | B24: Lunch | C24: Walmart Cheese Croissant (by croissant) | D24: 12 | E24: 1 | F24: 12 | G24: https://docs.google.com/open?id=1h9CmVCxFuDLMFbGBaBznFKnrVbxtmirpfh28FMmvHFA
A25: 46095 | B25: Lunch | C25: Orange | D25: 0.09 | E25: 0 | F25: 0 | G25: https://docs.google.com/open?id=1h9CmVCxFuDLMFbGBaBznFKnrVbxtmirpfh28FMmvHFA
A26: 46095 | B26: Lunch | C26: Tomatos (Raw) | D26: 0.03 | E26: 22 | F26: 0.7 | G26: https://docs.google.com/open?id=1h9CmVCxFuDLMFbGBaBznFKnrVbxtmirpfh28FMmvHFA
A27: 46095 | B27: Afternoon Snack | C27: Apple | D27: 0.13 | E27: 55 | F27: 7.2 | G27: https://docs.google.com/open?id=1h9CmVCxFuDLMFbGBaBznFKnrVbxtmirpfh28FMmvHFA
A28: 46095 | B28: Afternoon Snack | C28: Kraft Smooth Peanut Butter | D28: 0.13 | E28: 12 | F28: 1.6 | G28: https://docs.google.com/open?id=1h9CmVCxFuDLMFbGBaBznFKnrVbxtmirpfh28FMmvHFA
A29: 46095 | B29: Dinner | C29: Gusta Chickenless Nuggets | D29: 0.08 | E29: 40 | F29: 3.2 | G29: https://docs.google.com/open?id=1h9CmVCxFuDLMFbGBaBznFKnrVbxtmirpfh28FMmvHFA
... A36: 46094 | B36: Morning Snack | C36: Apple | D36: 0.13 | E36: 50 | F36: 6.5 | G36: https://docs.google.com/open?id=1dn6RtWI4bVAKo34n2gOlH7Fnf6Iz74c0wIpHxYBfVH0
A37: 46094 | B37: Morning Snack | C37: Orange | D37: 0.09 | E37: 0 | F37: n | G37: https://docs.google.com/open?id=1dn6RtWI4bVAKo34n2gOlH7Fnf6Iz74c0wIpHxYBfVH0
A38: 46094 | B38: Dinner | C38: Cavendish Flavour Crisp Fries | D38: 0.22 | E38: 45 | F38: 9.9 | G38: https://docs.google.com/open?id=1dn6RtWI4bVAKo34n2gOlH7Fnf6Iz74c0wIpHxYBfVH0
A39: 46094 | B39: Dinner | C39: Eggs | D39: 0 | E39: 2 | F39: 0 | G39: https://docs.google.com/open?id=1dn6RtWI4bVAKo34n2gOlH7Fnf6Iz74c0wIpHxYBfVH0
A40: 46094 | B40: Dinner | C40: Heinz Ketchup | D40: 0.33 | E40: 10 | F40: 3.3 | G40: https://docs.google.com/open?id=1dn6RtWI4bVAKo34n2gOlH7Fnf6Iz74c0wIpHxYBfVH0
A41: 46094 | B41: Dinner | C41: Dill Pickles | D41: 0.03 | E41: 33 | F41: 1 | G41: https://docs.google.com/open?id=1dn6RtWI4bVAKo34n2gOlH7Fnf6Iz74c0wIpHxYBfVH0
A42: 46093 | B42: Breakfast | C42: Eggs | D42: 0 | E42: 2 | F42: 0 | G42: https://docs.google.com/open?id=1wcUZA2AJJAnk_DF1yBKKxtgeMyEd3R2aHREKq4PwKlM
A43: 46093 | B43: Breakfast | C43: Heinz Ketchup | D43: 0.33 | E43: 12 | F43: 4 | G43: https://docs.google.com/open?id=1wcUZA2AJJAnk_DF1yBKKxtgeMyEd3R2aHREKq4PwKlM
A44: 46093 | B44: Breakfast | C44: Les Grains St-Méthode Multi-Cereal Bread (Per Slice) | D44: 10 | E44: 1 | F44: 10 | G44: https://docs.google.com/open?id=1wcUZA2AJJAnk_DF1yBKKxtgeMyEd3R2aHREKq4PwKlM
A45: 46093 | B45: Breakfast | C45: Apple | D45: 0.13 | E45: 50 | F45: 6.5 | G45: https://docs.google.com/open?id=1wcUZA2AJJAnk_DF1yBKKxtgeMyEd3R2aHREKq4PwKlM
A46: 46093 | B46: Lunch | C46: Compliments Hotdog Bun (Per Bun) | D46: 20 | E46: 1 | F46: 20 | G46: https://docs.google.com/open?id=1wcUZA2AJJAnk_DF1yBKKxtgeMyEd3R2aHREKq4PwKlM
A47: 46093 | B47: Lunch | C47: Light Life Smart Dogs (per weiner) | D47: 2 | E47: 1 | F47: 2 | G47: https://docs.google.com/open?id=1wcUZA2AJJAnk_DF1yBKKxtgeMyEd3R2aHREKq4PwKlM
A48: 46093 | B48: Lunch | C48: Veggies and Dip (per serving) | D48: 1 | E48: 1 | F48: 1 | G48: https://docs.google.com/open?id=1wcUZA2AJJAnk_DF1yBKKxtgeMyEd3R2aHREKq4PwKlM
...
